Workbook

Sheet Summary
A1: ECL Provisioning Summary & Commentary
A2: Generated: 03-Sep-2026 07:52
A4: Metric | B4: Q3FY26 | C4: Q4FY26 | D4: Change
A5: PORTFOLIO
A6: Number of loans | B6: 37 | C6: 37 | D6: =C6-B6
A7: Outstanding (Rs. Cr) | B7: 120.28 | C7: 117.36 | D7: =C7-B7
A8: ECL provision held (Rs. Cr) | B8: 15.192 | C8: 14.83 | D8: =C8-B8
A9: Provision coverage (%) | B9: 12.63 | C9: 12.64 | D9: =C9-B9
A10: STAGE 1
A11: Loans | B11: 24 | C11: 25 | D11: =C11-B11
A12: Outstanding (Rs. Cr) | B12: 83.67 | C12: 84.29 | D12: =C12-B12
A13: Provision (Rs. Cr) | B13: 0.76 | C13: 0.757 | D13: =C13-B13
A14: Share of book (%) | B14: 69.56 | C14: 71.82 | D14: =C14-B14
A15: STAGE 2
A16: Loans | B16: 6 | C16: 3 | D16: =C16-B16
A17: Outstanding (Rs. Cr) | B17: 17.72 | C17: 9.71 | D17: =C17-B17
A18: Provision (Rs. Cr) | B18: 2.856 | C18: 1.345 | D18: =C18-B18
A19: Share of book (%) | B19: 14.73 | C19: 8.27 | D19: =C19-B19
A20: STAGE 3
A21: Loans | B21: 7 | C21: 9 | D21: =C21-B21
A22: Outstanding (Rs. Cr) | B22: 18.89 | C22: 23.36 | D22: =C22-B22
A23: Provision (Rs. Cr) | B23: 11.576 | C23: 12.728 | D23: =C23-B23
A24: Share of book (%) | B24: 15.71 | C24: 19.9 | D24: =C24-B24
A27: COMMENTARY
A28: ECL PROVISIONING COMMENTARY — Q4FY26
A29: Comparison basis: Q3FY26 -> Q4FY26
A31: PORTFOLIO POSITION
A32: The book stood at Rs. 117.36 Cr across 37 loans as at Q4FY26. ECL provision held was Rs. 14.830 Cr, giving a coverage of 12.64% of the book.
A33: Against Q3FY26, the book has reduced by Rs. 2.92 Cr and provision has fallen by Rs. 0.362 Cr. Coverage improved by 0.01 percentage points.
A35: ASSET QUALITY BY STAGE
A36: Stage 1: 25 loans, Rs. 84.29 Cr (71.82% of the book) — up 2.26 pp.
A37: Stage 2: 3 loans, Rs. 9.71 Cr (8.27% of the book) — down 6.46 pp.
A38: Stage 3: 9 loans, Rs. 23.36 Cr (19.90% of the book) — up 4.19 pp.
A40: WHAT MOVED
A41: Deterioration — Rs. 7.80 Cr in total:
... A56: Basis: figures are taken as computed under Ind AS 109 and RBI norms in the source data. This draft has not independently verified them and requires Controller review before Board or Audit Committee submission.

Sheet Migration_Q3FY26_Q4FY26
A1: Migration Analysis: Q3FY26 → Q4FY26
A2: Each table below is headed with the actual periods being compared. Click any number to open the loan-level drill-down.
A4: A. IND AS 109 STAGE MIGRATION
A5: 1. ECL PROVISION HELD (Rs. Cr, as at later period)
A6: AS AT Q3FY26 ▾ | B6: AS AT Q4FY26
A7: Stage/Bucket | B7: Stage 1 | C7: Stage 2 | D7: Stage 3 | E7: Total
A8: Stage 1 | B8: 0.729 | C8: 0.464 | D8: 0 | E8: =SUM(B8:D8)
A9: Stage 2 | B9: 0.028 | C9: 0.881 | D9: 3.016 | E9: =SUM(B9:D9)
A10: Stage 3 | B10: 0 | C10: 0 | D10: 9.712 | E10: =SUM(B10:D10)
A11: Total | B11: =SUM(B8:B10) | C11: =SUM(C8:C10) | D11: =SUM(D8:D10) | E11: =SUM(E8:E10)
A13: 2. OUTSTANDING (Rs. Cr, as at later period)
A14: AS AT Q3FY26 ▾ | B14: AS AT Q4FY26
A15: Stage/Bucket | B15: Stage 1 | C15: Stage 2 | D15: Stage 3 | E15: Total
A16: Stage 1 | B16: 78.76 | C16: 2.85 | D16: 0 | E16: =SUM(B16:D16)
A17: Stage 2 | B17: 5.53 | C17: 6.86 | D17: 4.95 | E17: =SUM(B17:D17)
A18: Stage 3 | B18: 0 | C18: 0 | D18: 18.41 | E18: =SUM(B18:D18)
A19: Total | B19: =SUM(B16:B18) | C19: =SUM(C16:C18) | D19: =SUM(D16:D18) | E19: =SUM(E16:E18)
A21: 3. LOAN COUNT
A22: AS AT Q3FY26 ▾ | B22: AS AT Q4FY26
A23: Stage/Bucket | B23: Stage 1 | C23: Stage 2 | D23: Stage 3 | E23: Total
A24: Stage 1 | B24: 23 | C24: 1 | D24: 0 | E24: =SUM(B24:D24)
A25: Stage 2 | B25: 2 | C25: 2 | D25: 2 | E25: =SUM(B25:D25)
A26: Stage 3 | B26: 0 | C26: 0 | D26: 7 | E26: =SUM(B26:D26)
A27: Total | B27: =SUM(B24:B26) | C27: =SUM(C24:C26) | D27: =SUM(D24:D26) | E27: =SUM(E24:E26)
A29: B. DPD AGEING BUCKET MIGRATION
A30: 1. ECL PROVISION HELD (Rs. Cr, as at later period)
A31: AS AT Q3FY26 ▾ | B31: AS AT Q4FY26
A32: Stage/Bucket | B32: 0 (Current) | C32: 1-30 | D32: 31-60 | E32: 61-90 | F32: 91-120 | G32: 120+ | H32: Total
A33: 0 (Current) | B33: 0.607 | C33: 0.101 | D33: 0 | E33: 0 | F33: 0 | G33: 0 | H33: =SUM(B33:G33)
A34: 1-30 | B34: 0.021 | C34: 0 | D34: 0 | E34: 0.464 | F34: 0 | G34: 0 | H34: =SUM(B34:G34)
A35: 31-60 | B35: 0.003 | C35: 0.025 | D35: 0.542 | E35: 0 | F35: 1.866 | G35: 0 | H35: =SUM(B35:G35)
A36: 61-90 | B36: 0 | C36: 0 | D36: 0 | E36: 0.339 | F36: 0 | G36: 1.15 | H36: =SUM(B36:G36)
A37: 91-120 | B37: 0 | C37: 0 | D37: 0 | E37: 0 | F37: 0 | G37: 0 | H37: =SUM(B37:G37)
A38: 120+ | B38: 0 | C38: 0 | D38: 0 | E38: 0 | F38: 0 | G38: 9.712 | H38: =SUM(B38:G38)
A39: Total | B39: =SUM(B33:B38) | C39: =SUM(C33:C38) | D39: =SUM(D33:D38) | E39: =SUM(E33:E38) | F39: =SUM(F33:F38) | G39: =SUM(G33:G38) | H39: =SUM(H33:H38)
A41: 2. OUTSTANDING (Rs. Cr, as at later period)
A42: AS AT Q3FY26 ▾ | B42: AS AT Q4FY26
A43: Stage/Bucket | B43: 0 (Current) | C43: 1-30 | D43: 31-60 | E43: 61-90 | F43: 91-120 | G43: 120+ | H43: Total
A44: 0 (Current) | B44: 61.63 | C44: 13.91 | D44: 0 | E44: 0 | F44: 0 | G44: 0 | H44: =SUM(B44:G44)
A45: 1-30 | B45: 3.22 | C45: 0 | D45: 0 | E45: 2.85 | F45: 0 | G45: 0 | H45: =SUM(B45:G45)
...

Sheet Drilldown_Q3FY26_Q4FY26
A1: Loan-level Drill-down: Q3FY26 → Q4FY26
A2: << Back to Migration_Q3FY26_Q4FY26
A3: Every loan present in both periods, with its stage and DPD bucket in each. Use Excel's filter on the Movement / Stage / DPD Bucket columns to isolate any cell of the matrices.
A5: Stage (Q3FY26) | B5: Stage (Q4FY26) | C5: Movement | D5: LoanID | E5: CustomerName | F5: Product | G5: Branch | H5: Outstanding_Cr (Q3FY26) | I5: Outstanding_Cr (Q4FY26) | J5: Provision_Cr (Q3FY26) | K5: Provision_Cr (Q4FY26) | L5: DPD Bucket (Q3FY26) | M5: DPD Bucket (Q4FY26) | N5: DPD (Q3FY26) | O5: DPD (Q4FY26)
A6: Stage 2 | B6: Stage 3 | C6: Deteriorated | D6: L0002 | E6: Patel Engineering | F6: Equipment Finance | G6: Indore | H6: 2.03 | I6: 2.01 | J6: 0.342 | K6: 1.15 | L6: 61-90 | M6: 120+ | N6: 83 | O6: 186
A7: Stage 2 | B7: Stage 3 | C7: Deteriorated | D7: L0003 | E7: Verma Logistics | F7: LAP | G7: Ahmedabad | H7: 3 | I7: 2.94 | J7: 0.585 | K7: 1.866 | L7: 31-60 | M7: 91-120 | N7: 55 | O7: 94
A8: Stage 1 | B8: Stage 2 | C8: Deteriorated | D8: L0027 | E8: Malhotra Tools | F8: Business Loan | G8: Indore | H8: 2.93 | I8: 2.85 | J8: 0.022 | K8: 0.464 | L8: 1-30 | M8: 61-90 | N8: 25 | O8: 74
A9: Stage 2 | B9: Stage 1 | C9: Improved | D9: L0018 | E9: Sinha Plastics | F9: Business Loan | G9: Indore | H9: 5.29 | I9: 5.16 | J9: 1.147 | K9: 0.025 | L9: 31-60 | M9: 1-30 | N9: 55 | O9: 13
A10: Stage 2 | B10: Stage 1 | C10: Improved | D10: L0025 | E10: Thakur Transport | F10: LAP | G10: Pune | H10: 0.37 | I10: 0.37 | J10: 0.059 | K10: 0.003 | L10: 31-60 | M10: 0 (Current) | N10: 31 | O10: 0
A11: Stage 1 | B11: Stage 1 | C11: No change | D11: L0001 | E11: Sharma Textiles | F11: Business Loan | G11: Ahmedabad | H11: 3.02 | I11: 3 | J11: 0.042 | K11: 0.024 | L11: 0 (Current) | M11: 0 (Current) | N11: 0 | O11: 0
A12: Stage 1 | B12: Stage 1 | C12: No change | D12: L0004 | E12: Iyer Foods | F12: LAP | G12: Pune | H12: 0.79 | I12: 0.77 | J12: 0.008 | K12: 0.008 | L12: 1-30 | M12: 0 (Current) | N12: 30 | O12: 0
A13: Stage 3 | B13: Stage 3 | C13: No change | D13: L0005 | E13: Nair Constructions | F13: LAP | G13: Mumbai | H13: 5.13 | I13: 4.98 | J13: 3.089 | K13: 2.482 | L13: 120+ | M13: 120+ | N13: 252 | O13: 163
A14: Stage 1 | B14: Stage 1 | C14: No change | D14: L0006 | E14: Reddy Agro | F14: Equipment Finance | G14: Pune | H14: 5.65 | I14: 5.38 | J14: 0.049 | K14: 0.031 | L14: 0 (Current) | M14: 1-30 | N14: 0 | O14: 20
A15: Stage 3 | B15: Stage 3 | C15: No change | D15: L0008 | E15: Desai Pharma | F15: Business Loan | G15: Indore | H15: 2.18 | I15: 2.15 | J15: 1.525 | K15: 1.512 | L15: 120+ | M15: 120+ | N15: 133 | O15: 133
A16: Stage 1 | B16: Stage 1 | C16: No change | D16: L0009 | E16: Bose Electricals | F16: Equipment Finance | G16: Ahmedabad | H16: 4.14 | I16: 4.1 | J16: 0.031 | K16: 0.042 | L16: 0 (Current) | M16: 1-30 | N16: 0 | O16: 3
A17: Stage 2 | B17: Stage 2 | C17: No change | D17: L0010 | E17: Menon Traders | F17: Business Loan | G17: Pune | H17: 1.98 | I17: 1.92 | J17: 0.26 | K17: 0.339 | L17: 61-90 | M17: 61-90 | N17: 87 | O17: 87
... A42: Stage 1 | B42: Stage 1 | C42: No change | D42: L0040 | E42: Roy Bearings | F42: Business Loan | G42: Indore | H42: 3.46 | I42: 3.4 | J42: 0.04 | K42: 0.028 | L42: 0 (Current) | M42: 0 (Current) | N42: 0 | O42: 0

Sheet Product_Q3FY26_Q4FY26
A1: Product-wise Summary: Q3FY26 -> Q4FY26
A2: Every product line is shown in full below (no filter needed - see the Branch sheet for that).
A4: Product | B4: Loans (Q3FY26) | C4: Loans (Q4FY26) | D4: Outstanding (Q3FY26) | E4: Outstanding (Q4FY26) | F4: Δ Outstanding | G4: Provision (Q3FY26) | H4: Provision (Q4FY26) | I4: Δ Provision | J4: Stage 3 Share % (Q3FY26) | K4: Stage 3 Share % (Q4FY26) | L4: Δ Stage 3 Share (pp)
A5: LAP | B5: 12 | C5: 12 | D5: 38.26 | E5: 37.31 | F5: =E5-D5 | G5: 4.424 | H5: 5.104 | I5: =H5-G5 | J5: 13.41 | K5: 21.23 | L5: =K5-J5
A6: Business Loan | B6: 12 | C6: 12 | D6: 36 | E6: 35.1 | F6: =E6-D6 | G6: 6.865 | H6: 5.454 | I6: =H6-G6 | J6: 23.89 | K6: 23.93 | L6: =K6-J6
A7: Equipment Finance | B7: 7 | C7: 7 | D7: 29.85 | E7: 29.16 | F7: =E7-D7 | G7: 0.542 | H7: 1.432 | I7: =H7-G7 | J7: 0 | K7: 6.89 | L7: =K7-J7
A8: Working Capital | B8: 6 | C8: 6 | D8: 16.17 | E8: 15.79 | F8: =E8-D8 | G8: 3.361 | H8: 2.84 | I8: =H8-G8 | J8: 31.91 | K8: 31.86 | L8: =K8-J8

Sheet Branch_Q3FY26_Q4FY26
A1: Branch-wise Detail (filterable): Q3FY26 -> Q4FY26
A2: This is a live Excel Table. Use the filter dropdown on Branch (or Product/Stage) to isolate any subset - the Total row updates automatically to the visible rows, and the table itself grows automatically if more rows are added directly beneath it.
A4: LoanID | B4: CustomerName | C4: Branch | D4: Product | E4: Stage (Q3FY26) | F4: Stage (Q4FY26) | G4: Outstanding (Q3FY26) | H4: Outstanding (Q4FY26) | I4: Provision (Q3FY26) | J4: Provision (Q4FY26)
A5: L0001 | B5: Sharma Textiles | C5: Ahmedabad | D5: Business Loan | E5: Stage 1 | F5: Stage 1 | G5: 3.02 | H5: 3 | I5: 0.042 | J5: 0.024
A6: L0002 | B6: Patel Engineering | C6: Indore | D6: Equipment Finance | E6: Stage 2 | F6: Stage 3 | G6: 2.03 | H6: 2.01 | I6: 0.342 | J6: 1.15
A7: L0003 | B7: Verma Logistics | C7: Ahmedabad | D7: LAP | E7: Stage 2 | F7: Stage 3 | G7: 3 | H7: 2.94 | I7: 0.585 | J7: 1.866
A8: L0004 | B8: Iyer Foods | C8: Pune | D8: LAP | E8: Stage 1 | F8: Stage 1 | G8: 0.79 | H8: 0.77 | I8: 0.008 | J8: 0.008
A9: L0005 | B9: Nair Constructions | C9: Mumbai | D9: LAP | E9: Stage 3 | F9: Stage 3 | G9: 5.13 | H9: 4.98 | I9: 3.089 | J9: 2.482
A10: L0006 | B10: Reddy Agro | C10: Pune | D10: Equipment Finance | E10: Stage 1 | F10: Stage 1 | G10: 5.65 | H10: 5.38 | I10: 0.049 | J10: 0.031
A11: L0008 | B11: Desai Pharma | C11: Indore | D11: Business Loan | E11: Stage 3 | F11: Stage 3 | G11: 2.18 | H11: 2.15 | I11: 1.525 | J11: 1.512
A12: L0009 | B12: Bose Electricals | C12: Ahmedabad | D12: Equipment Finance | E12: Stage 1 | F12: Stage 1 | G12: 4.14 | H12: 4.1 | I12: 0.031 | J12: 0.042
A13: L0010 | B13: Menon Traders | C13: Pune | D13: Business Loan | E13: Stage 2 | F13: Stage 2 | G13: 1.98 | H13: 1.92 | I13: 0.26 | J13: 0.339
A14: L0011 | B14: Joshi Auto Parts | C14: Ahmedabad | D14: Working Capital | E14: Stage 1 | F14: Stage 1 | G14: 3.35 | H14: 3.28 | I14: 0.036 | J14: 0.031
A15: L0012 | B15: Gupta Packaging | C15: Ahmedabad | D15: Working Capital | E15: Stage 1 | F15: Stage 1 | G15: 2.55 | H15: 2.45 | I15: 0.031 | J15: 0.013
A16: L0013 | B16: Rao Chemicals | C16: Ahmedabad | D16: Equipment Finance | E16: Stage 1 | F16: Stage 1 | G16: 4.47 | H16: 4.32 | I16: 0.049 | J16: 0.04
... A41: L0040 | B41: Roy Bearings | C41: Indore | D41: Business Loan | E41: Stage 1 | F41: Stage 1 | G41: 3.46 | H41: 3.4 | I41: 0.04 | J41: 0.028
A42: Total | G42: =SUBTOTAL(109,G5:G41) | H42: =SUBTOTAL(109,H5:H41) | I42: =SUBTOTAL(109,I5:I41) | J42: =SUBTOTAL(109,J5:J41)

Sheet IndAS107_35H_Q3FY26_Q4FY26
A1: Ind AS 107 para 35H — Loss Allowance Reconciliation: Q3FY26 → Q4FY26
A2: Movement in ECL by category. Mapping used: 12-month ECL = Stage 1, Lifetime ECL (not credit-impaired) = Stage 2, Lifetime ECL (credit-impaired) = Stage 3 — verify this mapping against your Board-approved SICR policy.
A4: Movement | B4: Stage 1 | C4: Stage 2 | D4: Stage 3 | E4: Total
A5: Opening balance | B5: 0.76 | C5: 2.856 | D5: 11.576 | E5: =SUM(B5:D5)
A6: New assets originated | B6: 0 | C6: 0 | D6: 0 | E6: =SUM(B6:D6)
A7: Amounts written off | B7: 0 | C7: 0 | D7: 0 | E7: =SUM(B7:D7)
A8: Assets derecognised / repaid | B8: 0 | C8: 0 | D8: 0 | E8: =SUM(B8:D8)
A9: Transferred out to other stage | B9: -0.022 | C9: -2.133 | D9: 0 | E9: =SUM(B9:D9)
A10: Transferred in from other stage | B10: 0.028 | C10: 0.464 | D10: 3.016 | E10: =SUM(B10:D10)
A11: Net remeasurement (no stage change) | B11: -0.009 | C11: 0.158 | D11: -1.864 | E11: =SUM(B11:D11)
A12: Closing balance | B12: 0.757 | C12: 1.345 | D12: 12.728 | E12: =SUM(B12:D12)

Sheet IRACP_LoanWorking_Q4FY26
A1: IRACP Loan-level Working — Q4FY26
A2: Unsecured_Cr and the Provision column are live formulas (click any cell to see them) - change Outstanding_Cr or Secured_Cr and the provision recalculates automatically. Standard/Sub-standard/Loss rows carry their full outstanding under 'Unsecured_Cr' at their flat rate (Secured_Cr = 0) so one formula pattern works for every category.
A4: LoanID | B4: CustomerName | C4: Ind AS 109 Stage | D4: DPD | E4: IRACP_Category | F4: Outstanding_Cr | G4: Secured_Cr | H4: Unsecured_Cr | I4: Rate_Secured_pct | J4: Rate_Unsecured_pct | K4: IRACP Provision (Rs. Cr) | L4: Ind AS 109 ECL (Rs. Cr) | M4: Security_Basis | N4: Basis (rule applied)
A5: L0001 | B5: Sharma Textiles | C5: Stage 1 | D5: 0 | E5: Standard | F5: 3 | G5: 0 | H5: =F5-G5 | I5: 0 | J5: 0.004 | K5: =G5*I5+H5*J5 | L5: 0.024 | M5: n/a | N5: Standard asset, NBFC-ML - 0.40% flat [para 55]
A6: L0002 | B6: Patel Engineering | C6: Stage 3 | D6: 186 | E6: Sub-standard | F6: 2.01 | G6: 0 | H6: =F6-G6 | I6: 0 | J6: 0.1 | K6: =G6*I6+H6*J6 | L6: 1.15 | M6: n/a | N6: Sub-standard - 10% of total outstanding [para 32(1)]
A7: L0003 | B7: Verma Logistics | C7: Stage 3 | D7: 94 | E7: Sub-standard | F7: 2.94 | G7: 0 | H7: =F7-G7 | I7: 0 | J7: 0.1 | K7: =G7*I7+H7*J7 | L7: 1.866 | M7: n/a | N7: Sub-standard - 10% of total outstanding [para 32(1)]
A8: L0004 | B8: Iyer Foods | C8: Stage 1 | D8: 0 | E8: Standard | F8: 0.77 | G8: 0 | H8: =F8-G8 | I8: 0 | J8: 0.004 | K8: =G8*I8+H8*J8 | L8: 0.008 | M8: n/a | N8: Standard asset, NBFC-ML - 0.40% flat [para 55]
A9: L0005 | B9: Nair Constructions | C9: Stage 3 | D9: 163 | E9: Sub-standard | F9: 4.98 | G9: 0 | H9: =F9-G9 | I9: 0 | J9: 0.1 | K9: =G9*I9+H9*J9 | L9: 2.482 | M9: n/a | N9: Sub-standard - 10% of total outstanding [para 32(1)]
A10: L0006 | B10: Reddy Agro | C10: Stage 1 | D10: 20 | E10: Standard | F10: 5.38 | G10: 0 | H10: =F10-G10 | I10: 0 | J10: 0.004 | K10: =G10*I10+H10*J10 | L10: 0.031 | M10: n/a | N10: Standard asset, NBFC-ML - 0.40% flat [para 55]
A11: L0008 | B11: Desai Pharma | C11: Stage 3 | D11: 133 | E11: Sub-standard | F11: 2.15 | G11: 0 | H11: =F11-G11 | I11: 0 | J11: 0.1 | K11: =G11*I11+H11*J11 | L11: 1.512 | M11: n/a | N11: Sub-standard - 10% of total outstanding [para 32(1)]
A12: L0009 | B12: Bose Electricals | C12: Stage 1 | D12: 3 | E12: Standard | F12: 4.1 | G12: 0 | H12: =F12-G12 | I12: 0 | J12: 0.004 | K12: =G12*I12+H12*J12 | L12: 0.042 | M12: n/a | N12: Standard asset, NBFC-ML - 0.40% flat [para 55]
A13: L0010 | B13: Menon Traders | C13: Stage 2 | D13: 87 | E13: Standard | F13: 1.92 | G13: 0 | H13: =F13-G13 | I13: 0 | J13: 0.004 | K13: =G13*I13+H13*J13 | L13: 0.339 | M13: n/a | N13: Standard asset, NBFC-ML - 0.40% flat [para 55]
A14: L0011 | B14: Joshi Auto Parts | C14: Stage 1 | D14: 0 | E14: Standard | F14: 3.28 | G14: 0 | H14: =F14-G14 | I14: 0 | J14: 0.004 | K14: =G14*I14+H14*J14 | L14: 0.031 | M14: n/a | N14: Standard asset, NBFC-ML - 0.40% flat [para 55]
A15: L0012 | B15: Gupta Packaging | C15: Stage 1 | D15: 0 | E15: Standard | F15: 2.45 | G15: 0 | H15: =F15-G15 | I15: 0 | J15: 0.004 | K15: =G15*I15+H15*J15 | L15: 0.013 | M15: n/a | N15: Standard asset, NBFC-ML - 0.40% flat [para 55]
A16: L0013 | B16: Rao Chemicals | C16: Stage 1 | D16: 0 | E16: Standard | F16: 4.32 | G16: 0 | H16: =F16-G16 | I16: 0 | J16: 0.004 | K16: =G16*I16+H16*J16 | L16: 0.04 | M16: n/a | N16: Standard asset, NBFC-ML - 0.40% flat [para 55]
... A41: L0040 | B41: Roy Bearings | C41: Stage 1 | D41: 0 | E41: Standard | F41: 3.4 | G41: 0 | H41: =F41-G41 | I41: 0 | J41: 0.004 | K41: =G41*I41+H41*J41 | L41: 0.028 | M41: n/a | N41: Standard asset, NBFC-ML - 0.40% flat [para 55]

Sheet RBI_IRACP_Comparison_Q4FY26
A1: RBI IRACP vs Ind AS 109 Provisioning Comparison — Q4FY26
A2: Auto-computed per loan from DPD. NBFC-Middle Layer rates (RBI IRACP Directions, 2025 - para 51/52/53/32/55). Per RBI (NBFC – IRACP) Directions, 2025: where Ind AS 109 ECL is lower than the IRACP floor, the shortfall is appropriated from net profit after tax to a separate 'Impairment Reserve' (not reckoned for regulatory capital). Category totals below are live SUMIF formulas against the 'IRACP_LoanWorking_Q4FY26' sheet.
A4: IRACP Asset Category | B4: Rate(s) Applied | C4: Loan_Count | D4: Outstanding_Cr | E4: Secured_Cr | F4: Unsecured_Cr | G4: Ind_AS_109_ECL_Provision_Cr | H4: IRACP_Provision_Cr | I4: Excess/(Shortfall) of Ind AS 109 over IRACP_Cr
A5: Standard | B5: 0.40% of outstanding [para 55] | C5: =COUNTIF(IRACP_LoanWorking_Q4FY26!E5:E41,A5) | D5: =SUMIF(IRACP_LoanWorking_Q4FY26!E5:E41,A5,IRACP_LoanWorking_Q4FY26!F5:F41) | E5: =SUMIF(IRACP_LoanWorking_Q4FY26!E5:E41,A5,IRACP_LoanWorking_Q4FY26!G5:G41) | F5: =SUMIF(IRACP_LoanWorking_Q4FY26!E5:E41,A5,IRACP_LoanWorking_Q4FY26!H5:H41) | G5: =SUMIF(IRACP_LoanWorking_Q4FY26!E5:E41,A5,IRACP_LoanWorking_Q4FY26!L5:L41) | H5: =SUMIF(IRACP_LoanWorking_Q4FY26!E5:E41,A5,IRACP_LoanWorking_Q4FY26!K5:K41) | I5: =G5-H5
A6: Sub-standard | B6: 10% of outstanding [para 32(1)] | C6: =COUNTIF(IRACP_LoanWorking_Q4FY26!E5:E41,A6) | D6: =SUMIF(IRACP_LoanWorking_Q4FY26!E5:E41,A6,IRACP_LoanWorking_Q4FY26!F5:F41) | E6: =SUMIF(IRACP_LoanWorking_Q4FY26!E5:E41,A6,IRACP_LoanWorking_Q4FY26!G5:G41) | F6: =SUMIF(IRACP_LoanWorking_Q4FY26!E5:E41,A6,IRACP_LoanWorking_Q4FY26!H5:H41) | G6: =SUMIF(IRACP_LoanWorking_Q4FY26!E5:E41,A6,IRACP_LoanWorking_Q4FY26!L5:L41) | H6: =SUMIF(IRACP_LoanWorking_Q4FY26!E5:E41,A6,IRACP_LoanWorking_Q4FY26!K5:K41) | I6: =G6-H6
A7: TOTAL | C7: =SUM(C5:C6) | D7: =SUM(D5:D6) | E7: =SUM(E5:E6) | F7: =SUM(F5:F6) | G7: =SUM(G5:G6) | H7: =SUM(H5:H6) | I7: =SUM(I5:I6)
A9: RESULT: Ind AS 109 provision meets or exceeds the IRACP floor. No Impairment Reserve appropriation required.

Sheet IRACP_Assumptions_Q4FY26
A1: IRACP Computation — Assumptions Register — Q4FY26
A2: Where realisable security value was not supplied, doubtful assets are treated as fully unsecured. Per para 32(2)(i) this can only OVERSTATE the prudential floor, never understate it. Supply Secured_Value_Cr to refine.
A4: Assumption | B4: Regulatory basis | C4: Effect on IRACP floor | D4: Loans affected | E4: Outstanding affected (Rs. Cr) | F4: IRACP provision on these loans (Rs. Cr)
A5: None - realisable security value was supplied for every doubtful asset | B5: Para 32(2) | C5: Nil | D5: 0 | E5: 0 | F5: 0
